Workbook

Sheet Cable
A1: seqNo | B1: cabTag | C1: cabDesignLen | D1: cabSpec | E1: wBS | F1: fromEqpTag | G1: toEqpTag | H1: pullCardNo | I1: routeDetails
A2: 1 | B2: Cabletag001 | C2: 233 | D2: Cabletype01 | E2: SS03 | F2: a | G2: b | H2: x | I2: S
A3: 2 | B3: Cabletag002 | C3: 478 | D3: Cabletype01 | E3: SS03 | F3: a | G3: b | H3: x | I3: y
A4: 3 | B4: Cabletag003 | C4: 630 | D4: Cabletype01 | E4: SS01 | F4: a | G4: b | H4: x | I4: y
A5: 4 | B5: Cabletag004 | C5: 122 | D5: Cabletype02 | E5: SS02 | F5: a | G5: b | H5: x | I5: y
A6: 5 | B6: Cabletag005 | C6: 86 | D6: Cabletype03 | E6: SS03 | F6: a | G6: b | H6: x | I6: y
A7: 6 | B7: Cabletag006 | C7: 740 | D7: Cabletype02 | E7: SS01 | F7: a | G7: b | H7: x | I7: y
A8: 7 | B8: Cabletag007 | C8: =547-50 -> 497 | D8: Cabletype03 | E8: SS02 | F8: a | G8: b | H8: x | I8: y
A9: 8 | B9: Cabletag008 | C9: 677 | D9: Cabletype01 | E9: SS02 | F9: a | G9: b | H9: x | I9: y
A10: 9 | B10: Cabletag009 | C10: 515 | D10: Cabletype03 | E10: SS03 | F10: a | G10: b | H10: x | I10: y
A11: 10 | B11: Cabletag010 | C11: 511 | D11: Cabletype03 | E11: SS01 | F11: a | G11: b | H11: x | I11: y
A12: 11 | B12: Cabletag011 | C12: 230 | D12: Cabletype03 | E12: SS02 | F12: a | G12: b | H12: x | I12: y
A13: 12 | B13: Cabletag012 | C13: 219 | D13: Cabletype03 | E13: SS01 | F13: a | G13: b | H13: x | I13: y
A14: 13 | B14: Cabletag013 | C14: 191 | D14: Cabletype01 | E14: SS01 | F14: a | G14: b | H14: x | I14: y
A15: 14 | B15: Cabletag014 | C15: 608 | D15: Cabletype02 | E15: SS03 | F15: a | G15: b | H15: x | I15: y
A16: 15 | B16: Cabletag015 | C16: 302 | D16: Cabletype02 | E16: SS03 | F16: a | G16: b | H16: x | I16: y
A17: 16 | B17: Cabletag016 | C17: 326 | D17: Cabletype01 | E17: SS02 | F17: a | G17: b | H17: x | I17: y
A18: 17 | B18: Cabletag017 | C18: 218 | D18: Cabletype03 | E18: SS02 | F18: a | G18: b | H18: x | I18: y
A19: 18 | B19: Cabletag018 | C19: 451 | D19: Cabletype01 | E19: SS01 | F19: a | G19: b | H19: x | I19: y
A20: 19 | B20: Cabletag019 | C20: 307 | D20: Cabletype03 | E20: SS01 | F20: a | G20: b | H20: x | I20: y
... A986: 985 | B986: Cabletag985 | C986: 200 | D986: Cabletype01 | E986: SS03 | F986: a | G986: b | H986: x | I986: y

Sheet Drum
A1: seqNo | B1: drumTag | C1: cabSpec | D1: manufLength | E1: designLength | F1: LenxDiainmm | G1: weightKg | H1: geoLocation
A2: 1 | B2: Drum001 | C2: Cabletype03 | D2: 1055 | E2: 1178 | F2: =RANDBETWEEN(20,25)/10 & "x" & RANDBETWEEN(10,15)/10 -> 2.2x1.5 | G2: =ROUND(0.5*LEFT(F2,FIND("x",F2,1)-1)*RIGHT(F2,LEN(F2)-FIND("x",F2,1))^2*1000,0) -> 2475 | H2: =VLOOKUP(RANDBETWEEN(1,432),DrumCopySql!A:J,10,0) -> 25.110376,55.129633
A3: 2 | B3: Drum002 | C3: Cabletype01 | D3: 1190 | E3: 1179 | F3: =RANDBETWEEN(20,25)/10 & "x" & RANDBETWEEN(10,15)/10 -> 2.1x1.4 | G3: =ROUND(0.5*LEFT(F3,FIND("x",F3,1)-1)*RIGHT(F3,LEN(F3)-FIND("x",F3,1))^2*1000,0) -> 2058 | H3: =VLOOKUP(RANDBETWEEN(1,432),DrumCopySql!A:J,10,0) -> 25.110376,55.12144
A4: 3 | B4: Drum003 | C4: Cabletype01 | D4: 1095 | E4: 1180 | F4: =RANDBETWEEN(20,25)/10 & "x" & RANDBETWEEN(10,15)/10 -> 2x1.2 | G4: =ROUND(0.5*LEFT(F4,FIND("x",F4,1)-1)*RIGHT(F4,LEN(F4)-FIND("x",F4,1))^2*1000,0) -> 1440 | H4: =VLOOKUP(RANDBETWEEN(1,432),DrumCopySql!A:J,10,0) -> 25.110376,55.147383
A5: 4 | B5: Drum004 | C5: Cabletype02 | D5: 1198 | E5: 1181 | F5: =RANDBETWEEN(20,25)/10 & "x" & RANDBETWEEN(10,15)/10 -> 2.4x1.5 | G5: =ROUND(0.5*LEFT(F5,FIND("x",F5,1)-1)*RIGHT(F5,LEN(F5)-FIND("x",F5,1))^2*1000,0) -> 2700 | H5: =VLOOKUP(RANDBETWEEN(1,432),DrumCopySql!A:J,10,0) -> 25.110376,55.139285
A6: 5 | B6: Drum005 | C6: Cabletype02 | D6: 1102 | E6: 1182 | F6: =RANDBETWEEN(20,25)/10 & "x" & RANDBETWEEN(10,15)/10 -> 2.2x1.5 | G6: =ROUND(0.5*LEFT(F6,FIND("x",F6,1)-1)*RIGHT(F6,LEN(F6)-FIND("x",F6,1))^2*1000,0) -> 2475 | H6: =VLOOKUP(RANDBETWEEN(1,432),DrumCopySql!A:J,10,0) -> 25.110376,55.132141
A7: 6 | B7: Drum006 | C7: Cabletype03 | D7: 1182 | E7: 1183 | F7: =RANDBETWEEN(20,25)/10 & "x" & RANDBETWEEN(10,15)/10 -> 2.5x1.2 | G7: =ROUND(0.5*LEFT(F7,FIND("x",F7,1)-1)*RIGHT(F7,LEN(F7)-FIND("x",F7,1))^2*1000,0) -> 1800 | H7: =VLOOKUP(RANDBETWEEN(1,432),DrumCopySql!A:J,10,0) -> 25.110376,55.121218
A8: 7 | B8: Drum007 | C8: Cabletype02 | D8: 1052 | E8: 1184 | F8: =RANDBETWEEN(20,25)/10 & "x" & RANDBETWEEN(10,15)/10 -> 2.1x1.5 | G8: =ROUND(0.5*LEFT(F8,FIND("x",F8,1)-1)*RIGHT(F8,LEN(F8)-FIND("x",F8,1))^2*1000,0) -> 2363 | H8: =VLOOKUP(RANDBETWEEN(1,432),DrumCopySql!A:J,10,0) -> 25.110376,55.122103
A9: 8 | B9: Drum008 | C9: Cabletype02 | D9: 1064 | E9: 1185 | F9: =RANDBETWEEN(20,25)/10 & "x" & RANDBETWEEN(10,15)/10 -> 2.5x1 | G9: =ROUND(0.5*LEFT(F9,FIND("x",F9,1)-1)*RIGHT(F9,LEN(F9)-FIND("x",F9,1))^2*1000,0) -> 1250 | H9: =VLOOKUP(RANDBETWEEN(1,432),DrumCopySql!A:J,10,0) -> 25.110376,55.141906
A10: 9 | B10: Drum009 | C10: Cabletype02 | D10: 1123 | E10: 1186 | F10: =RANDBETWEEN(20,25)/10 & "x" & RANDBETWEEN(10,15)/10 -> 2.2x1.3 | G10: =ROUND(0.5*LEFT(F10,FIND("x",F10,1)-1)*RIGHT(F10,LEN(F10)-FIND("x",F10,1))^2*1000,0) -> 1859 | H10: =VLOOKUP(RANDBETWEEN(1,432),DrumCopySql!A:J,10,0) -> 25.110376,55.132741
A11: 10 | B11: Drum010 | C11: Cabletype03 | D11: 1062 | E11: 1187 | F11: =RANDBETWEEN(20,25)/10 & "x" & RANDBETWEEN(10,15)/10 -> 2.4x1.2 | G11: =ROUND(0.5*LEFT(F11,FIND("x",F11,1)-1)*RIGHT(F11,LEN(F11)-FIND("x",F11,1))^2*1000,0) -> 1728 | H11: =VLOOKUP(RANDBETWEEN(1,432),DrumCopySql!A:J,10,0) -> 25.110376,55.140649
A12: 11 | B12: Drum011 | C12: Cabletype03 | D12: 1113 | E12: 1188 | F12: =RANDBETWEEN(20,25)/10 & "x" & RANDBETWEEN(10,15)/10 -> 2.1x1.2 | G12: =ROUND(0.5*LEFT(F12,FIND("x",F12,1)-1)*RIGHT(F12,LEN(F12)-FIND("x",F12,1))^2*1000,0) -> 1512 | H12: =VLOOKUP(RANDBETWEEN(1,432),DrumCopySql!A:J,10,0) -> 25.110376,55.128892
A13: 12 | B13: Drum012 | C13: Cabletype03 | D13: 1166 | E13: 1189 | F13: =RANDBETWEEN(20,25)/10 & "x" & RANDBETWEEN(10,15)/10 -> 2.1x1.5 | G13: =ROUND(0.5*LEFT(F13,FIND("x",F13,1)-1)*RIGHT(F13,LEN(F13)-FIND("x",F13,1))^2*1000,0) -> 2363 | H13: =VLOOKUP(RANDBETWEEN(1,432),DrumCopySql!A:J,10,0) -> 25.110376,55.136609
... A428: 427 | B428: Drum427 | C428: Cabletype02 | D428: 1091 | E428: 1604 | F428: =RANDBETWEEN(20,25)/10 & "x" & RANDBETWEEN(10,15)/10 -> 2.2x1.2 | G428: =ROUND(0.5*LEFT(F428,FIND("x",F428,1)-1)*RIGHT(F428,LEN(F428)-FIND("x",F428,1))^2*1000,0) -> 1584 | H428: =VLOOKUP(RANDBETWEEN(1,432),DrumCopySql!A:J,10,0) -> 25.110376,55.134398

Sheet drum_range
A1: cabSpec | B1: Min | C1: Max
A2: Cabletype03 | B2: 500 | C2: 1000
A3: Cabletype01 | B3: 600 | C3: 1500
A4: Cabletype02 | B4: 400 | C4: 4500

Sheet drum_share
A1: cabSpec | B1: Min_share_length
A2: Cabletype03 | B2: 100
A3: Cabletype01 | B3: 250
A4: Cabletype02 | B4: 75

Sheet CableList
A1: uid | B1: cabTag | C1: cabSegNo | D1: cableSpec | E1: fromEqpTag | F1: toEqpTag | G1: cabDesignLen | H1: cableSegLen | I1: pullCardNo | J1: drumTag | K1: mesLength | L1: cabCutLength | M1: cabLaidLen | N1: sheathMarkStart | O1: sheathMarkEnd | P1: isCut | Q1: isLaid | R1: siteNotes | S1: modified | T1: modifiedBy | U1: approvalStatus | V1: siteimgURL | W1: siteDataStream | X1: udf2 | Y1: udf3 | Z1: udf4 | AA1: udf5 | AB1: routeDetails
A2: 200 | B2: cab0 | D2: ="type-0"&RANDBETWEEN(1,3) -> type-03 | E2: ="fromTag-"&RIGHT(B2,LEN(B2)-FIND("cab",B2)-2) -> fromTag-0 | F2: ="toTag-"&RIGHT(B2,LEN(B2)-FIND("cab",B2)-2) -> toTag-0 | G2: =RANDBETWEEN(275,400) -> 391 | I2: ="PC_"&B2 -> PC_cab0 | AB2: =VLOOKUP(RANDBETWEEN(1,10),#REF!,3,0) -> #REF!
A3: 201 | B3: cab1 | D3: ="type-0"&RANDBETWEEN(1,3) -> type-03 | E3: ="fromTag-"&RIGHT(B3,LEN(B3)-FIND("cab",B3)-2) -> fromTag-1 | F3: ="toTag-"&RIGHT(B3,LEN(B3)-FIND("cab",B3)-2) -> toTag-1 | G3: =RANDBETWEEN(275,400) -> 306 | I3: ="PC_"&B3 -> PC_cab1 | AB3: =VLOOKUP(RANDBETWEEN(1,10),#REF!,3,0) -> #REF!
A4: 202 | B4: cab2 | D4: ="type-0"&RANDBETWEEN(1,3) -> type-03 | E4: ="fromTag-"&RIGHT(B4,LEN(B4)-FIND("cab",B4)-2) -> fromTag-2 | F4: ="toTag-"&RIGHT(B4,LEN(B4)-FIND("cab",B4)-2) -> toTag-2 | G4: =RANDBETWEEN(275,400) -> 296 | I4: ="PC_"&B4 -> PC_cab2 | AB4: =VLOOKUP(RANDBETWEEN(1,10),#REF!,3,0) -> #REF!
A5: 203 | B5: cab3 | D5: ="type-0"&RANDBETWEEN(1,3) -> type-02 | E5: ="fromTag-"&RIGHT(B5,LEN(B5)-FIND("cab",B5)-2) -> fromTag-3 | F5: ="toTag-"&RIGHT(B5,LEN(B5)-FIND("cab",B5)-2) -> toTag-3 | G5: =RANDBETWEEN(275,400) -> 340 | I5: ="PC_"&B5 -> PC_cab3 | AB5: =VLOOKUP(RANDBETWEEN(1,10),#REF!,3,0) -> #REF!
A6: 204 | B6: cab4 | D6: ="type-0"&RANDBETWEEN(1,3) -> type-01 | E6: ="fromTag-"&RIGHT(B6,LEN(B6)-FIND("cab",B6)-2) -> fromTag-4 | F6: ="toTag-"&RIGHT(B6,LEN(B6)-FIND("cab",B6)-2) -> toTag-4 | G6: =RANDBETWEEN(275,400) -> 290 | I6: ="PC_"&B6 -> PC_cab4 | AB6: =VLOOKUP(RANDBETWEEN(1,10),#REF!,3,0) -> #REF!
A7: 205 | B7: cab5 | D7: ="type-0"&RANDBETWEEN(1,3) -> type-01 | E7: ="fromTag-"&RIGHT(B7,LEN(B7)-FIND("cab",B7)-2) -> fromTag-5 | F7: ="toTag-"&RIGHT(B7,LEN(B7)-FIND("cab",B7)-2) -> toTag-5 | G7: =RANDBETWEEN(275,400) -> 299 | I7: ="PC_"&B7 -> PC_cab5 | AB7: =VLOOKUP(RANDBETWEEN(1,10),#REF!,3,0) -> #REF!
A8: 206 | B8: cab6 | D8: ="type-0"&RANDBETWEEN(1,3) -> type-03 | E8: ="fromTag-"&RIGHT(B8,LEN(B8)-FIND("cab",B8)-2) -> fromTag-6 | F8: ="toTag-"&RIGHT(B8,LEN(B8)-FIND("cab",B8)-2) -> toTag-6 | G8: =RANDBETWEEN(275,400) -> 275 | I8: ="PC_"&B8 -> PC_cab6 | AB8: =VLOOKUP(RANDBETWEEN(1,10),#REF!,3,0) -> #REF!
A9: 207 | B9: cab7 | D9: ="type-0"&RANDBETWEEN(1,3) -> type-01 | E9: ="fromTag-"&RIGHT(B9,LEN(B9)-FIND("cab",B9)-2) -> fromTag-7 | F9: ="toTag-"&RIGHT(B9,LEN(B9)-FIND("cab",B9)-2) -> toTag-7 | G9: =RANDBETWEEN(275,400) -> 339 | I9: ="PC_"&B9 -> PC_cab7 | AB9: =VLOOKUP(RANDBETWEEN(1,10),#REF!,3,0) -> #REF!
A10: 208 | B10: cab8 | D10: ="type-0"&RANDBETWEEN(1,3) -> type-01 | E10: ="fromTag-"&RIGHT(B10,LEN(B10)-FIND("cab",B10)-2) -> fromTag-8 | F10: ="toTag-"&RIGHT(B10,LEN(B10)-FIND("cab",B10)-2) -> toTag-8 | G10: =RANDBETWEEN(275,400) -> 352 | I10: ="PC_"&B10 -> PC_cab8 | AB10: =VLOOKUP(RANDBETWEEN(1,10),#REF!,3,0) -> #REF!
A11: 209 | B11: cab9 | D11: ="type-0"&RANDBETWEEN(1,3) -> type-02 | E11: ="fromTag-"&RIGHT(B11,LEN(B11)-FIND("cab",B11)-2) -> fromTag-9 | F11: ="toTag-"&RIGHT(B11,LEN(B11)-FIND("cab",B11)-2) -> toTag-9 | G11: =RANDBETWEEN(275,400) -> 327 | I11: ="PC_"&B11 -> PC_cab9 | AB11: =VLOOKUP(RANDBETWEEN(1,10),#REF!,3,0) -> #REF!
A12: 210 | B12: cab10 | D12: ="type-0"&RANDBETWEEN(1,3) -> type-01 | E12: ="fromTag-"&RIGHT(B12,LEN(B12)-FIND("cab",B12)-2) -> fromTag-10 | F12: ="toTag-"&RIGHT(B12,LEN(B12)-FIND("cab",B12)-2) -> toTag-10 | G12: =RANDBETWEEN(275,400) -> 284 | I12: ="PC_"&B12 -> PC_cab10 | AB12: =VLOOKUP(RANDBETWEEN(1,10),#REF!,3,0) -> #REF!
A13: 211 | B13: cab11 | D13: ="type-0"&RANDBETWEEN(1,3) -> type-02 | E13: ="fromTag-"&RIGHT(B13,LEN(B13)-FIND("cab",B13)-2) -> fromTag-11 | F13: ="toTag-"&RIGHT(B13,LEN(B13)-FIND("cab",B13)-2) -> toTag-11 | G13: =RANDBETWEEN(275,400) -> 313 | I13: ="PC_"&B13 -> PC_cab11 | AB13: =VLOOKUP(RANDBETWEEN(1,10),#REF!,3,0) -> #REF!
... A1600: 1798 | B1600: cab1598 | D1600: ="type-0"&RANDBETWEEN(1,3) -> type-03 | E1600: ="fromTag-"&RIGHT(B1600,LEN(B1600)-FIND("cab",B1600)-2) -> fromTag-1598 | F1600: ="toTag-"&RIGHT(B1600,LEN(B1600)-FIND("cab",B1600)-2) -> toTag-1598 | G1600: =RANDBETWEEN(275,400) -> 368 | I1600: ="PC_"&B1600 -> PC_cab1598 | AB1600: =VLOOKUP(RANDBETWEEN(1,10),#REF!,3,0) -> #REF!

Sheet DrumList
A1: uid | B1: drumTag | C1: cableSpec | D1: manufLength | E1: designLength | F1: LenxDiainmm | G1: weightKg | H1: cutLength | I1: commLength | J1: geoLocation
A2: 100 | B2: Drum0 | C2: type-02 | D2: 1178 | E2: =ROUND(D2*(1+RANDBETWEEN(5,20)/1000),0) -> 1193 | F2: =RANDBETWEEN(20,25)/10 & "x" & RANDBETWEEN(10,15)/10 -> 2.2x1.3 | G2: =0.5*LEFT(F2,FIND("x",F2,1)-1)*RIGHT(F2,LEN(F2)-FIND("x",F2,1))^2 -> 1.859 | J2: =VLOOKUP(RANDBETWEEN(1,432),DrumCopySql!A:J,10,0) -> 25.110376,55.135358
A3: 101 | B3: Drum1 | C3: type-03 | D3: 1095 | E3: =ROUND(D3*(1+RANDBETWEEN(5,20)/1000),0) -> 1115 | F3: =RANDBETWEEN(20,25)/10 & "x" & RANDBETWEEN(10,15)/10 -> 2.2x1 | G3: =0.5*LEFT(F3,FIND("x",F3,1)-1)*RIGHT(F3,LEN(F3)-FIND("x",F3,1))^2 -> 1.1 | J3: =VLOOKUP(RANDBETWEEN(1,432),DrumCopySql!A:J,10,0) -> 25.110376,55.148857
A4: 102 | B4: Drum2 | C4: type-02 | D4: 1099 | E4: =ROUND(D4*(1+RANDBETWEEN(5,20)/1000),0) -> 1115 | F4: =RANDBETWEEN(20,25)/10 & "x" & RANDBETWEEN(10,15)/10 -> 2.2x1.4 | G4: =0.5*LEFT(F4,FIND("x",F4,1)-1)*RIGHT(F4,LEN(F4)-FIND("x",F4,1))^2 -> 2.156 | J4: =VLOOKUP(RANDBETWEEN(1,432),DrumCopySql!A:J,10,0) -> 25.110376,55.123189
A5: 103 | B5: Drum3 | C5: type-02 | D5: 1053 | E5: =ROUND(D5*(1+RANDBETWEEN(5,20)/1000),0) -> 1059 | F5: =RANDBETWEEN(20,25)/10 & "x" & RANDBETWEEN(10,15)/10 -> 2x1.5 | G5: =0.5*LEFT(F5,FIND("x",F5,1)-1)*RIGHT(F5,LEN(F5)-FIND("x",F5,1))^2 -> 2.25 | J5: =VLOOKUP(RANDBETWEEN(1,432),DrumCopySql!A:J,10,0) -> 25.110376,55.126161
A6: 104 | B6: Drum4 | C6: type-02 | D6: 1069 | E6: =ROUND(D6*(1+RANDBETWEEN(5,20)/1000),0) -> 1089 | F6: =RANDBETWEEN(20,25)/10 & "x" & RANDBETWEEN(10,15)/10 -> 2x1.4 | G6: =0.5*LEFT(F6,FIND("x",F6,1)-1)*RIGHT(F6,LEN(F6)-FIND("x",F6,1))^2 -> 1.96 | J6: =VLOOKUP(RANDBETWEEN(1,432),DrumCopySql!A:J,10,0) -> 25.110376,55.117362
A7: 105 | B7: Drum5 | C7: type-03 | D7: 1165 | E7: =ROUND(D7*(1+RANDBETWEEN(5,20)/1000),0) -> 1184 | F7: =RANDBETWEEN(20,25)/10 & "x" & RANDBETWEEN(10,15)/10 -> 2.4x1.2 | G7: =0.5*LEFT(F7,FIND("x",F7,1)-1)*RIGHT(F7,LEN(F7)-FIND("x",F7,1))^2 -> 1.728 | J7: =VLOOKUP(RANDBETWEEN(1,432),DrumCopySql!A:J,10,0) -> 25.110376,55.148466
A8: 106 | B8: Drum6 | C8: type-03 | D8: 1154 | E8: =ROUND(D8*(1+RANDBETWEEN(5,20)/1000),0) -> 1166 | F8: =RANDBETWEEN(20,25)/10 & "x" & RANDBETWEEN(10,15)/10 -> 2.1x1.3 | G8: =0.5*LEFT(F8,FIND("x",F8,1)-1)*RIGHT(F8,LEN(F8)-FIND("x",F8,1))^2 -> 1.7745 | J8: =VLOOKUP(RANDBETWEEN(1,432),DrumCopySql!A:J,10,0) -> 25.110376,55.12106
A9: 107 | B9: Drum7 | C9: type-02 | D9: 1080 | E9: =ROUND(D9*(1+RANDBETWEEN(5,20)/1000),0) -> 1091 | F9: =RANDBETWEEN(20,25)/10 & "x" & RANDBETWEEN(10,15)/10 -> 2.1x1.2 | G9: =0.5*LEFT(F9,FIND("x",F9,1)-1)*RIGHT(F9,LEN(F9)-FIND("x",F9,1))^2 -> 1.512 | J9: =VLOOKUP(RANDBETWEEN(1,432),DrumCopySql!A:J,10,0) -> 25.110376,55.110928
A10: 108 | B10: Drum8 | C10: type-03 | D10: 1191 | E10: =ROUND(D10*(1+RANDBETWEEN(5,20)/1000),0) -> 1214 | F10: =RANDBETWEEN(20,25)/10 & "x" & RANDBETWEEN(10,15)/10 -> 2.4x1 | G10: =0.5*LEFT(F10,FIND("x",F10,1)-1)*RIGHT(F10,LEN(F10)-FIND("x",F10,1))^2 -> 1.2 | J10: =VLOOKUP(RANDBETWEEN(1,432),DrumCopySql!A:J,10,0) -> 25.110376,55.13684
A11: 109 | B11: Drum9 | C11: type-01 | D11: 1112 | E11: =ROUND(D11*(1+RANDBETWEEN(5,20)/1000),0) -> 1134 | F11: =RANDBETWEEN(20,25)/10 & "x" & RANDBETWEEN(10,15)/10 -> 2.1x1.4 | G11: =0.5*LEFT(F11,FIND("x",F11,1)-1)*RIGHT(F11,LEN(F11)-FIND("x",F11,1))^2 -> 2.058 | J11: =VLOOKUP(RANDBETWEEN(1,432),DrumCopySql!A:J,10,0) -> 25.110376,55.149328
A12: 110 | B12: Drum10 | C12: type-01 | D12: 1177 | E12: =ROUND(D12*(1+RANDBETWEEN(5,20)/1000),0) -> 1196 | F12: =RANDBETWEEN(20,25)/10 & "x" & RANDBETWEEN(10,15)/10 -> 2.1x1.4 | G12: =0.5*LEFT(F12,FIND("x",F12,1)-1)*RIGHT(F12,LEN(F12)-FIND("x",F12,1))^2 -> 2.058 | J12: =VLOOKUP(RANDBETWEEN(1,432),DrumCopySql!A:J,10,0) -> 25.110376,55.143204
A13: 111 | B13: Drum11 | C13: type-03 | D13: 1118 | E13: =ROUND(D13*(1+RANDBETWEEN(5,20)/1000),0) -> 1130 | F13: =RANDBETWEEN(20,25)/10 & "x" & RANDBETWEEN(10,15)/10 -> 2.1x1 | G13: =0.5*LEFT(F13,FIND("x",F13,1)-1)*RIGHT(F13,LEN(F13)-FIND("x",F13,1))^2 -> 1.05 | J13: =VLOOKUP(RANDBETWEEN(1,432),DrumCopySql!A:J,10,0) -> 25.110376,55.133705
... A600: 698 | B600: Drum598 | C600: type-03 | D600: 1627 | E600: =ROUND(D600*(1+RANDBETWEEN(5,20)/1000),0) -> 1637 | F600: =RANDBETWEEN(20,25)/10 & "x" & RANDBETWEEN(10,15)/10 -> 2.1x1.1 | G600: =0.5*LEFT(F600,FIND("x",F600,1)-1)*RIGHT(F600,LEN(F600)-FIND("x",F600,1))^2 -> 1.2705 | J600: =VLOOKUP(RANDBETWEEN(1,432),DrumCopySql!A:J,10,0) -> 25.110376,55.123921

Sheet cableCopySql
A1: uid | B1: cabTag | C1: cabSegNo | D1: cableSpec | E1: fromEqpTag | F1: toEqpTag | G1: cabDesignLen | H1: cableSegLen | I1: pullCardNo | J1: drumTag | K1: mesLength | L1: cabCutLength | M1: cabLaidLen | N1: sheathMarkStart | O1: sheathMarkEnd | P1: isCut | Q1: isLaid | R1: siteNotes | S1: modified | T1: modifiedBy | U1: approvalStatus | V1: imagePath | W1: udf1 | X1: udf2 | Y1: udf3 | Z1: udf4 | AA1: udf5
A2: 81 | B2: B1TCP12-266 | C2: -- | D2: 0.6/1kV_A_LC_Non-FR_5Cx2.5 | E2: fromEqpTag168 | F2: toEqpTag168 | G2: 315 | H2: 315 | I2: PC_B1TCP12-266 | J2: C-L-5C2.5-D038 | K2: 0 | L2: 0 | M2: 0 | N2: 0 | O2: 0 | P2: 0 | Q2: 0 | S2: 44187 | T2: KaushikRay | U2: Pending | V2: sites/Elecsense/Lists/cableTable1 | X2: NULL | Y2: NULL | Z2: NULL
A3: 82 | B3: A2BM310-267 | C3: -- | D3: 0.6/1kV_A_LC_Non-FR_5Cx2.5 | E3: fromEqpTag169 | F3: toEqpTag169 | G3: 10 | H3: 10 | I3: PC_A2BM310-267 | J3: C-L-5C2.5-D038 | K3: 0 | L3: 0 | M3: 0 | N3: 0 | O3: 0 | P3: 0 | Q3: 0 | S3: 44187 | T3: KaushikRay | U3: Pending | V3: sites/Elecsense/Lists/cableTable1 | X3: NULL | Y3: NULL | Z3: NULL
A4: 83 | B4: A6HDB00-268 | C4: -- | D4: 0.6/1kV_A_LC_Non-FR_5Cx2.5 | E4: fromEqpTag170 | F4: toEqpTag170 | G4: 674 | H4: 674 | I4: PC_A6HDB00-268 | J4: C-L-5C2.5-D039 | K4: 0 | L4: 0 | M4: 0 | N4: 0 | O4: 0 | P4: 0 | Q4: 0 | S4: 44187 | T4: KaushikRay | U4: Pending | V4: sites/Elecsense/Lists/cableTable1 | X4: NULL | Y4: NULL | Z4: NULL
A5: 84 | B5: B1TCP12-269 | C5: -- | D5: 0.6/1kV_A_LC_Non-FR_5Cx2.5 | E5: fromEqpTag171 | F5: toEqpTag171 | G5: 315 | H5: 315 | I5: PC_B1TCP12-269 | J5: C-L-5C2.5-D039 | K5: 0 | L5: 0 | M5: 0 | N5: 0 | O5: 0 | P5: 0 | Q5: 0 | S5: 44187 | T5: KaushikRay | U5: Pending | V5: sites/Elecsense/Lists/cableTable1 | X5: NULL | Y5: NULL | Z5: NULL
A6: 85 | B6: A2BM310-270 | C6: -- | D6: 0.6/1kV_A_LC_Non-FR_5Cx2.5 | E6: fromEqpTag172 | F6: toEqpTag172 | G6: 10 | H6: 10 | I6: PC_A2BM310-270 | J6: C-L-5C2.5-D039 | K6: 0 | L6: 0 | M6: 0 | N6: 0 | O6: 0 | P6: 0 | Q6: 0 | S6: 44187 | T6: KaushikRay | U6: Pending | V6: sites/Elecsense/Lists/cableTable1 | X6: NULL | Y6: NULL | Z6: NULL
A7: 86 | B7: B1SWBD0-394 | C7: -- | D7: 0.6/1kV_A_LC_Non-FR_10Cx2.5 | E7: fromEqpTag296 | F7: toEqpTag296 | G7: 320 | H7: 320 | I7: PC_B1SWBD0-394 | J7: C-L-10C2.5-D110 | K7: 0 | L7: 0 | M7: 0 | N7: 0 | O7: 0 | P7: 0 | Q7: 0 | S7: 44187 | T7: KaushikRay | U7: Pending | V7: sites/Elecsense/Lists/cableTable1 | X7: NULL | Y7: NULL | Z7: NULL
A8: 87 | B8: B1SWBD0-395 | C8: -- | D8: 0.6/1kV_A_LC_Non-FR_10Cx2.5 | E8: fromEqpTag297 | F8: toEqpTag297 | G8: 320 | H8: 320 | I8: PC_B1SWBD0-395 | J8: C-L-10C2.5-D110 | K8: 0 | L8: 0 | M8: 0 | N8: 0 | O8: 0 | P8: 0 | Q8: 0 | S8: 44187 | T8: KaushikRay | U8: Pending | V8: sites/Elecsense/Lists/cableTable1 | X8: NULL | Y8: NULL | Z8: NULL
A9: 88 | B9: B1RCP03-396 | C9: -- | D9: 0.6/1kV_A_LC_Non-FR_10Cx2.5 | E9: fromEqpTag298 | F9: toEqpTag298 | G9: 320 | H9: 320 | I9: PC_B1RCP03-396 | J9: C-L-10C2.5-D110 | K9: 0 | L9: 0 | M9: 0 | N9: 0 | O9: 0 | P9: 0 | Q9: 0 | S9: 44187 | T9: KaushikRay | U9: Pending | V9: sites/Elecsense/Lists/cableTable1 | X9: NULL | Y9: NULL | Z9: NULL
A10: 89 | B10: B1SWBD0-448 | C10: -- | D10: 0.6/1kV_A_LC_Non-FR_10Cx2.5 | E10: fromEqpTag350 | F10: toEqpTag350 | G10: 330 | H10: 330 | I10: PC_B1SWBD0-448 | J10: C-L-10C2.5-D156 | K10: 0 | L10: 0 | M10: 0 | N10: 0 | O10: 0 | P10: 0 | Q10: 0 | S10: 44187 | T10: KaushikRay | U10: Pending | V10: sites/Elecsense/Lists/cableTable1 | X10: NULL | Y10: NULL | Z10: NULL
A11: 90 | B11: B1RCP00-449 | C11: -- | D11: 0.6/1kV_A_LC_Non-FR_10Cx2.5 | E11: fromEqpTag351 | F11: toEqpTag351 | G11: 350 | H11: 350 | I11: PC_B1RCP00-449 | J11: C-L-10C2.5-D156 | K11: 0 | L11: 0 | M11: 0 | N11: 0 | O11: 0 | P11: 0 | Q11: 0 | S11: 44187 | T11: KaushikRay | U11: Pending | V11: sites/Elecsense/Lists/cableTable1 | X11: NULL | Y11: NULL | Z11: NULL
A12: 91 | B12: B1SWBD0-450 | C12: -- | D12: 0.6/1kV_A_LC_Non-FR_10Cx2.5 | E12: fromEqpTag352 | F12: toEqpTag352 | G12: 320 | H12: 320 | I12: PC_B1SWBD0-450 | J12: C-L-10C2.5-D156 | K12: 0 | L12: 0 | M12: 0 | N12: 0 | O12: 0 | P12: 0 | Q12: 0 | S12: 44187 | T12: KaushikRay | U12: Pending | V12: sites/Elecsense/Lists/cableTable1 | X12: NULL | Y12: NULL | Z12: NULL
A13: 92 | B13: B1ACUPS-119 | C13: -- | D13: 0.6/1kV_A_LC_Non-FR_3Cx2.5 | E13: fromEqpTag21 | F13: toEqpTag21 | G13: 384 | H13: 384 | I13: PC_B1ACUPS-119 | J13: C-L-3C2.5-D010 | K13: 0 | L13: 0 | M13: 0 | N13: 0 | O13: 0 | P13: 0 | Q13: 0 | S13: 44187 | T13: KaushikRay | U13: Pending | V13: sites/Elecsense/Lists/cableTable1 | X13: NULL | Y13: NULL | Z13: NULL
... A46: 125 | B46: A3GM110-273 | C46: -- | D46: 0.6/1kV_A_LC_Non-FR_5Cx2.5 | E46: fromEqpTag175 | F46: toEqpTag175 | G46: 5 | H46: 5 | I46: PC_A3GM110-273 | J46: C-L-5C2.5-D041 | K46: 0 | L46: 0 | M46: 0 | N46: 0 | O46: 0 | P46: 0 | Q46: 0 | S46: 44187 | T46: KaushikRay | U46: Pending | V46: sites/Elecsense/Lists/cableTable1 | X46: NULL | Y46: NULL | Z46: NULL
A47: 126 | B47: B1SWBD0-274 | C47: -- | D47: 0.6/1kV_A_LC_Non-FR_10Cx2.5 | E47: fromEqpTag176 | F47: toEqpTag176 | G47: 555 | H47: 555 | I47: PC_B1SWBD0-274 | J47: C-L-10C2.5-D001 | K47: 100 | L47: 0 | M47: 0 | N47: 100 | O47: 200 | P47: 0 | Q47: 0 | R47: Testtesttest | S47: 44276 | T47: KaushikRay | U47: Pending | V47: sites/Elecsense/Lists/cableTable1 | X47: NULL | Y47: NULL | Z47: NULL
A48: 127 | B48: B1SWBD0-275 | C48: -- | D48: 0.6/1kV_A_LC_Non-FR_10Cx2.5 | E48: fromEqpTag177 | F48: toEqpTag177 | G48: 440 | H48: 440 | I48: PC_B1SWBD0-275 | J48: C-L-10C2.5-D001 | K48: 0 | L48: 0 | M48: 0 | N48: 0 | O48: 0 | P48: 0 | Q48: 0 | S48: 44187 | T48: KaushikRay | U48: Pending | V48: sites/Elecsense/Lists/cableTable1 | X48: NULL | Y48: NULL | Z48: NULL
A49: 128 | B49: B1SWBD0-276 | C49: -- | D49: 0.6/1kV_A_LC_Non-FR_10Cx2.5 | E49: fromEqpTag178 | F49: toEqpTag178 | G49: 633 | H49: 633 | I49: PC_B1SWBD0-276 | J49: C-L-10C2.5-D002 | K49: 0 | L49: 0 | M49: 0 | N49: 0 | O49: 0 | P49: 0 | Q49: 0 | S49: 44276 | T49: KaushikRay | U49: Pending | V49: sites/Elecsense/Lists/cableTable1 | X49: NULL | Y49: NULL | Z49: NULL
A50: 129 | B50: B1SWBD0-277 | C50: -- | D50: 0.6/1kV_A_LC_Non-FR_10Cx2.5 | E50: fromEqpTag179 | F50: toEqpTag179 | G50: 322 | H50: 322 | I50: PC_B1SWBD0-277 | J50: C-L-10C2.5-D002 | K50: 0 | L50: 0 | M50: 0 | N50: 0 | O50: 0 | P50: 0 | Q50: 0 | S50: 44276 | T50: KaushikRay | U50: Pending | V50: sites/Elecsense/Lists/cableTable1 | X50: NULL | Y50: NULL | Z50: NULL
A51: 130 | B51: B1SWBD0-278 | C51: -- | D51: 0.6/1kV_A_LC_Non-FR_10Cx2.5 | E51: fromEqpTag180 | F51: toEqpTag180 | G51: 622 | H51: 622 | I51: PC_B1SWBD0-278 | J51: C-L-10C2.5-D003 | K51: 0 | L51: 0 | M51: 0 | N51: 0 | O51: 0 | P51: 0 | Q51: 0 | S51: 44276 | T51: KaushikRay | U51: Pending | V51: sites/Elecsense/Lists/cableTable1 | X51: NULL | Y51: NULL | Z51: NULL
A52: 131 | B52: B1SWBD0-279 | C52: -- | D52: 0.6/1kV_A_LC_Non-FR_10Cx2.5 | E52: fromEqpTag181 | F52: toEqpTag181 | G52: 330 | H52: 330 | I52: PC_B1SWBD0-279 | J52: C-L-10C2.5-D003 | K52: 0 | L52: 0 | M52: 0 | N52: 0 | O52: 0 | P52: 0 | Q52: 0 | S52: 44214 | T52: KaushikRay | U52: Pending | V52: sites/Elecsense/Lists/cableTable1 | X52: NULL | Y52: NULL | Z52: NULL
A53: 132 | B53: B1SWBD0-280 | C53: -- | D53: 0.6/1kV_A_LC_Non-FR_10Cx2.5 | E53: fromEqpTag182 | F53: toEqpTag182 | G53: 628 | H53: 628 | I53: PC_B1SWBD0-280 | J53: C-L-10C2.5-D004 | K53: 0 | L53: 0 | M53: 0 | N53: 0 | O53: 0 | P53: 0 | Q53: 0 | S53: 44187 | T53: KaushikRay | U53: Pending | V53: sites/Elecsense/Lists/cableTable1 | X53: NULL | Y53: NULL | Z53: NULL
A54: 133 | B54: B1SWBD0-281 | C54: -- | D54: 0.6/1kV_A_LC_Non-FR_10Cx2.5 | E54: fromEqpTag183 | F54: toEqpTag183 | G54: 327 | H54: 327 | I54: PC_B1SWBD0-281 | J54: C-L-10C2.5-D004 | K54: 0 | L54: 0 | M54: 0 | N54: 0 | O54: 0 | P54: 0 | Q54: 0 | S54: 44187 | T54: KaushikRay | U54: Pending | V54: sites/Elecsense/Lists/cableTable1 | X54: NULL | Y54: NULL | Z54: NULL
A55: 134 | B55: B1SWBD0-282 | C55: -- | D55: 0.6/1kV_A_LC_Non-FR_10Cx2.5 | E55: fromEqpTag184 | F55: toEqpTag184 | G55: 647 | H55: 647 | I55: PC_B1SWBD0-282 | J55: C-L-10C2.5-D005 | K55: 0 | L55: 0 | M55: 0 | N55: 0 | O55: 0 | P55: 0 | Q55: 0 | S55: 44187 | T55: KaushikRay | U55: Pending | V55: sites/Elecsense/Lists/cableTable1 | X55: NULL | Y55: NULL | Z55: NULL
A56: 135 | B56: B1RCP00-283 | C56: Segment1 | D56: 0.6/1kV_A_LC_Non-FR_10Cx2.5 | E56: fromEqpTag185 | F56: toEqpTag185 | G56: 1230 | H56: 298 | I56: PC_B1RCP00-283 | J56: C-L-10C2.5-D005-1 | K56: 0 | L56: 0 | M56: 0 | N56: 0 | O56: 0 | P56: 0 | Q56: 0 | S56: 44187 | T56: KaushikRay | U56: Pending | V56: sites/Elecsense/Lists/cableTable1 | X56: NULL | Y56: NULL | Z56: NULL
A57: 136 | B57: B1SWBD0-284 | C57: -- | D57: 0.6/1kV_A_LC_Non-FR_10Cx2.5 | E57: fromEqpTag186 | F57: toEqpTag186 | G57: 893 | H57: 893 | I57: PC_B1SWBD0-284 | J57: C-L-10C2.5-D006 | K57: 0 | L57: 0 | M57: 0 | N57: 0 | O57: 0 | P57: 0 | Q57: 0 | S57: 44206 | T57: KaushikRay | U57: Pending | V57: sites/Elecsense/Lists/cableTable1 | X57: NULL | Y57: NULL | Z57: NULL
A58: 137 | B58: B1SWBD0-285 | C58: Segment2 | D58: 0.6/1kV_A_LC_Non-FR_10Cx2.5 | E58: fromEqpTag187 | F58: toEqpTag187 | G58: 1045 | H58: 52 | I58: PC_B1SWBD0-285 | J58: C-L-10C2.5-D006 | K58: 0 | L58: 0 | M58: 0 | N58: 0 | O58: 0 | P58: 0 | Q58: 0 | S58: 44187 | T58: KaushikRay | U58: Pending | V58: sites/Elecsense/Lists/cableTable1 | X58: NULL | Y58: NULL | Z58: NULL
A59: 138 | B59: B1SWBD0-294 | C59: -- | D59: 0.6/1kV_A_LC_Non-FR_10Cx2.5 | E59: fromEqpTag196 | F59: toEqpTag196 | G59: 597 | H59: 597 | I59: PC_B1SWBD0-294 | J59: C-L-10C2.5-D017 | K59: 0 | L59: 0 | M59: 0 | N59: 0 | O59: 0 | P59: 0 | Q59: 0 | S59: 44187 | T59: KaushikRay | U59: Pending | V59: sites/Elecsense/Lists/cableTable1 | X59: NULL | Y59: NULL | Z59: NULL
... A629: 708 | B629: B1SWBD0-324 | C629: Segment3 | D629: 0.6/1kV_A_LC_Non-FR_10Cx2.5 | E629: fromEqpTag720 | F629: toEqpTag720 | G629: 2069 | H629: 995 | I629: PC_B1SWBD0-324 | J629: C-L-10C2.5-D379 | K629: 0 | L629: 0 | M629: 0 | N629: 0 | O629: 0 | P629: 0 | Q629: 0 | S629: 44187 | T629: KaushikRay | U629: Pending | V629: sites/Elecsense/Lists/cableTable1 | X629: NULL | Y629: NULL | Z629: NULL
A630: 709 | G630: NULL | H630: NULL | L630: NULL | M630: NULL | N630: NULL | O630: NULL | P630: NULL | Q630: NULL | S630: NULL | X630: NULL | Y630: NULL | Z630: NULL
A631: 1 | B631: A1HDB00-179 | C631: -- | D631: 0.6/1kV_A_LC_Non-FR_5Cx2.5 | E631: fromEqpTag81 | F631: toEqpTag81 | G631: 962 | H631: 962 | I631: PC_A1HDB00-179 | J631: C-L-5C2.5-D002 | K631: 200 | L631: 0 | M631: 0 | N631: 0 | O631: 0 | P631: 0 | Q631: 0 | R631: Testtest | S631: 44288 | T631: KaushikRay | U631: Pending | V631: sites/Elecsense/Lists/cableTable1 | X631: NULL | Y631: NULL | Z631: NULL
A632: 2 | B632: A2BM210-180 | C632: -- | D632: 0.6/1kV_A_LC_Non-FR_5Cx2.5 | E632: fromEqpTag82 | F632: toEqpTag82 | G632: 10 | H632: 10 | I632: PC_A2BM210-180 | J632: C-L-5C2.5-D002 | K632: 0 | L632: 0 | M632: 0 | N632: 0 | O632: 0 | P632: 1 | Q632: 1 | S632: 44187 | T632: KaushikRay | U632: Pending | V632: sites/Elecsense/Lists/cableTable1 | X632: NULL | Y632: NULL | Z632: NULL
A633: 3 | B633: A7BM080-181 | C633: -- | D633: 0.6/1kV_A_LC_Non-FR_5Cx2.5 | E633: fromEqpTag83 | F633: toEqpTag83 | G633: 10 | H633: 10 | I633: PC_A7BM080-181 | J633: C-L-5C2.5-D002 | K633: 250 | L633: 0 | M633: 0 | N633: 110 | O633: 360 | P633: 1 | Q633: 1 | R633: Alldone. | S633: 44272 | T633: KaushikRay | U633: Pending | V633: sites/Elecsense/Lists/cableTable1 | X633: NULL | Y633: NULL | Z633: NULL
A634: 4 | B634: A7BM080-182 | C634: -- | D634: 0.6/1kV_A_LC_Non-FR_5Cx2.5 | E634: fromEqpTag84 | F634: toEqpTag84 | G634: 10 | H634: 10 | I634: PC_A7BM080-182 | J634: C-L-5C2.5-D002 | K634: 200 | L634: 0 | M634: 0 | N634: 100 | O634: 300 | P634: 1 | Q634: 1 | R634: workisstoppedduetorain | S634: 44288 | T634: KaushikRay | U634: Pending | V634: sites/Elecsense/Lists/cableTable1 | X634: NULL | Y634: NULL | Z634: NULL
A635: 5 | B635: A3GM010-183 | C635: -- | D635: 0.6/1kV_A_LC_Non-FR_5Cx2.5 | E635: fromEqpTag85 | F635: toEqpTag85 | G635: 5 | H635: 5 | I635: PC_A3GM010-183 | J635: C-L-5C2.5-D002 | K635: 0 | L635: 0 | M635: 0 | N635: 0 | O635: 0 | P635: 1 | Q635: 1 | S635: 44187 | T635: KaushikRay | U635: Pending | V635: sites/Elecsense/Lists/cableTable1 | X635: NULL | Y635: NULL | Z635: NULL
A636: 6 | B636: B1TCP13-221 | C636: -- | D636: 0.6/1kV_A_LC_Non-FR_5Cx2.5 | E636: fromEqpTag123 | F636: toEqpTag123 | G636: 670 | H636: 670 | I636: PC_B1TCP13-221 | J636: C-L-5C2.5-D022 | K636: 0 | L636: 0 | M636: 0 | N636: 0 | O636: 0 | P636: 1 | Q636: 1 | S636: 44187 | T636: KaushikRay | U636: Pending | V636: sites/Elecsense/Lists/cableTable1 | X636: NULL | Y636: NULL | Z636: NULL
A637: 7 | B637: B1TCP12-222 | C637: -- | D637: 0.6/1kV_A_LC_Non-FR_5Cx2.5 | E637: fromEqpTag124 | F637: toEqpTag124 | G637: 315 | H637: 315 | I637: PC_B1TCP12-222 | J637: C-L-5C2.5-D022 | K637: 0 | L637: 0 | M637: 0 | N637: 0 | O637: 0 | P637: 1 | Q637: 1 | S637: 44187 | T637: KaushikRay | U637: Pending | V637: sites/Elecsense/Lists/cableTable1 | X637: NULL | Y637: NULL | Z637: NULL
A638: 8 | B638: A2BM310-223 | C638: -- | D638: 0.6/1kV_A_LC_Non-FR_5Cx2.5 | E638: fromEqpTag125 | F638: toEqpTag125 | G638: 10 | H638: 10 | I638: PC_A2BM310-223 | J638: C-L-5C2.5-D022 | K638: 0 | L638: 0 | M638: 0 | N638: 0 | O638: 0 | P638: 1 | Q638: 1 | S638: 44187 | T638: KaushikRay | U638: Pending | V638: sites/Elecsense/Lists/cableTable1 | X638: NULL | Y638: NULL | Z638: NULL
A639: 9 | B639: SealGa-224 | C639: -- | D639: 0.6/1kV_A_LC_Non-FR_5Cx2.5 | E639: fromEqpTag126 | F639: toEqpTag126 | G639: 5 | H639: 5 | I639: PC_SealGa-224 | J639: C-L-5C2.5-D022 | K639: 0 | L639: 0 | M639: 0 | N639: 0 | O639: 0 | P639: 1 | Q639: 1 | S639: 44187 | T639: KaushikRay | U639: Pending | V639: sites/Elecsense/Lists/cableTable1 | X639: NULL | Y639: NULL | Z639: NULL
A640: 10 | B640: B1ACUPS-125 | C640: -- | D640: 0.6/1kV_A_LC_Non-FR_3Cx2.5 | E640: fromEqpTag27 | F640: toEqpTag27 | G640: 279 | H640: 279 | I640: PC_B1ACUPS-125 | J640: C-L-3C2.5-D013 | K640: 0 | L640: 0 | M640: 0 | N640: 0 | O640: 0 | P640: 1 | Q640: 1 | S640: 44187 | T640: KaushikRay | U640: Pending | V640: sites/Elecsense/Lists/cableTable1 | X640: NULL | Y640: NULL | Z640: NULL
A641: 11 | B641: B1DCUPS-126 | C641: -- | D641: 0.6/1kV_A_LC_Non-FR_3Cx2.5 | E641: fromEqpTag28 | F641: toEqpTag28 | G641: 279 | H641: 279 | I641: PC_B1DCUPS-126 | J641: C-L-3C2.5-D013 | K641: 0 | L641: 0 | M641: 0 | N641: 0 | O641: 0 | P641: 0 | Q641: 0 | S641: 44187 | T641: KaushikRay | U641: Pending | V641: sites/Elecsense/Lists/cableTable1 | X641: NULL | Y641: NULL | Z641: NULL
...

Sheet Sheet3
A1: uid | B1: cabTag | C1: cabSegNo | D1: cabSpec | E1: fromEqpTag | F1: toEqpTag | G1: cabDesignLen | H1: wBS | I1: cableSegLen | J1: pullCardNo | K1: drumTag | L1: mesLength | M1: cabCutLength | N1: cabLaidLen | O1: sheathMarkStart | P1: sheathMarkEnd | Q1: isCut | R1: isLaid | S1: siteNotes | T1: modified | U1: modifiedBy | V1: approvalStatus | W1: siteimgURL | X1: siteDataStream | Y1: udf2 | Z1: udf3 | AA1: udf4 | AB1: udf5 | AC1: routeDetails
A2: 1 | B2: B1TCP12-266 | C2: -- | D2: 0.6/1kV_A_LC_Non-FR_5Cx2.5 | E2: fromEqpTag168 | F2: toEqpTag168 | G2: 315 | H2: SS01 | I2: 315 | J2: PC_B1TCP12-266 | K2: C-L-5C2.5-D038 | L2: 0 | M2: 0 | N2: 0 | O2: 0 | P2: 0 | Q2: 0 | R2: 0 | T2: 44187 | U2: KaushikRay | V2: Pending | W2: sites/Elecsense/Lists/cableTable1 | Y2: NULL | Z2: NULL | AA2: NULL
A3: 2 | B3: A2BM310-267 | C3: -- | D3: 0.6/1kV_A_LC_Non-FR_5Cx2.5 | E3: fromEqpTag169 | F3: toEqpTag169 | G3: 10 | H3: SS01 | I3: 10 | J3: PC_A2BM310-267 | K3: C-L-5C2.5-D038 | L3: 0 | M3: 0 | N3: 0 | O3: 0 | P3: 0 | Q3: 0 | R3: 0 | T3: 44187 | U3: KaushikRay | V3: Pending | W3: sites/Elecsense/Lists/cableTable1 | Y3: NULL | Z3: NULL | AA3: NULL
A4: 3 | B4: A6HDB00-268 | C4: -- | D4: 0.6/1kV_A_LC_Non-FR_5Cx2.5 | E4: fromEqpTag170 | F4: toEqpTag170 | G4: 674 | H4: SS01 | I4: 674 | J4: PC_A6HDB00-268 | K4: C-L-5C2.5-D039 | L4: 0 | M4: 0 | N4: 0 | O4: 0 | P4: 0 | Q4: 0 | R4: 0 | T4: 44187 | U4: KaushikRay | V4: Pending | W4: sites/Elecsense/Lists/cableTable1 | Y4: NULL | Z4: NULL | AA4: NULL
A5: 4 | B5: B1TCP12-269 | C5: -- | D5: 0.6/1kV_A_LC_Non-FR_5Cx2.5 | E5: fromEqpTag171 | F5: toEqpTag171 | G5: 315 | H5: SS01 | I5: 315 | J5: PC_B1TCP12-269 | K5: C-L-5C2.5-D039 | L5: 0 | M5: 0 | N5: 0 | O5: 0 | P5: 0 | Q5: 0 | R5: 0 | T5: 44187 | U5: KaushikRay | V5: Pending | W5: sites/Elecsense/Lists/cableTable1 | Y5: NULL | Z5: NULL | AA5: NULL
A6: 5 | B6: A2BM310-270 | C6: -- | D6: 0.6/1kV_A_LC_Non-FR_5Cx2.5 | E6: fromEqpTag172 | F6: toEqpTag172 | G6: 10 | H6: SS01 | I6: 10 | J6: PC_A2BM310-270 | K6: C-L-5C2.5-D039 | L6: 0 | M6: 0 | N6: 0 | O6: 0 | P6: 0 | Q6: 0 | R6: 0 | T6: 44187 | U6: KaushikRay | V6: Pending | W6: sites/Elecsense/Lists/cableTable1 | Y6: NULL | Z6: NULL | AA6: NULL
A7: 6 | B7: B1SWBD0-394 | C7: -- | D7: 0.6/1kV_A_LC_Non-FR_10Cx2.5 | E7: fromEqpTag296 | F7: toEqpTag296 | G7: 320 | H7: SS01 | I7: 320 | J7: PC_B1SWBD0-394 | K7: C-L-10C2.5-D110 | L7: 0 | M7: 0 | N7: 0 | O7: 0 | P7: 0 | Q7: 0 | R7: 0 | T7: 44187 | U7: KaushikRay | V7: Pending | W7: sites/Elecsense/Lists/cableTable1 | Y7: NULL | Z7: NULL | AA7: NULL
A8: 7 | B8: B1SWBD0-395 | C8: -- | D8: 0.6/1kV_A_LC_Non-FR_10Cx2.5 | E8: fromEqpTag297 | F8: toEqpTag297 | G8: 320 | H8: SS01 | I8: 320 | J8: PC_B1SWBD0-395 | K8: C-L-10C2.5-D110 | L8: 0 | M8: 0 | N8: 0 | O8: 0 | P8: 0 | Q8: 0 | R8: 0 | T8: 44187 | U8: KaushikRay | V8: Pending | W8: sites/Elecsense/Lists/cableTable1 | Y8: NULL | Z8: NULL | AA8: NULL
A9: 8 | B9: B1RCP03-396 | C9: -- | D9: 0.6/1kV_A_LC_Non-FR_10Cx2.5 | E9: fromEqpTag298 | F9: toEqpTag298 | G9: 320 | H9: SS01 | I9: 320 | J9: PC_B1RCP03-396 | K9: C-L-10C2.5-D110 | L9: 0 | M9: 0 | N9: 0 | O9: 0 | P9: 0 | Q9: 0 | R9: 0 | T9: 44187 | U9: KaushikRay | V9: Pending | W9: sites/Elecsense/Lists/cableTable1 | Y9: NULL | Z9: NULL | AA9: NULL
A10: 9 | B10: B1SWBD0-448 | C10: -- | D10: 0.6/1kV_A_LC_Non-FR_10Cx2.5 | E10: fromEqpTag350 | F10: toEqpTag350 | G10: 330 | H10: SS01 | I10: 330 | J10: PC_B1SWBD0-448 | K10: C-L-10C2.5-D156 | L10: 0 | M10: 0 | N10: 0 | O10: 0 | P10: 0 | Q10: 0 | R10: 0 | T10: 44187 | U10: KaushikRay | V10: Pending | W10: sites/Elecsense/Lists/cableTable1 | Y10: NULL | Z10: NULL | AA10: NULL
A11: 10 | B11: B1RCP00-449 | C11: -- | D11: 0.6/1kV_A_LC_Non-FR_10Cx2.5 | E11: fromEqpTag351 | F11: toEqpTag351 | G11: 350 | H11: SS01 | I11: 350 | J11: PC_B1RCP00-449 | K11: C-L-10C2.5-D156 | L11: 0 | M11: 0 | N11: 0 | O11: 0 | P11: 0 | Q11: 0 | R11: 0 | T11: 44187 | U11: KaushikRay | V11: Pending | W11: sites/Elecsense/Lists/cableTable1 | Y11: NULL | Z11: NULL | AA11: NULL
A12: 11 | B12: B1SWBD0-450 | C12: -- | D12: 0.6/1kV_A_LC_Non-FR_10Cx2.5 | E12: fromEqpTag352 | F12: toEqpTag352 | G12: 320 | H12: SS01 | I12: 320 | J12: PC_B1SWBD0-450 | K12: C-L-10C2.5-D156 | L12: 0 | M12: 0 | N12: 0 | O12: 0 | P12: 0 | Q12: 0 | R12: 0 | T12: 44187 | U12: KaushikRay | V12: Pending | W12: sites/Elecsense/Lists/cableTable1 | Y12: NULL | Z12: NULL | AA12: NULL
A13: 12 | B13: B1ACUPS-119 | C13: -- | D13: 0.6/1kV_A_LC_Non-FR_3Cx2.5 | E13: fromEqpTag21 | F13: toEqpTag21 | G13: 384 | H13: SS01 | I13: 384 | J13: PC_B1ACUPS-119 | K13: C-L-3C2.5-D010 | L13: 0 | M13: 0 | N13: 0 | O13: 0 | P13: 0 | Q13: 0 | R13: 0 | T13: 44187 | U13: KaushikRay | V13: Pending | W13: sites/Elecsense/Lists/cableTable1 | Y13: NULL | Z13: NULL | AA13: NULL
... A46: 45 | B46: A3GM110-273 | C46: -- | D46: 0.6/1kV_A_LC_Non-FR_5Cx2.5 | E46: fromEqpTag175 | F46: toEqpTag175 | G46: 5 | H46: SS01 | I46: 5 | J46: PC_A3GM110-273 | K46: C-L-5C2.5-D041 | L46: 0 | M46: 0 | N46: 0 | O46: 0 | P46: 0 | Q46: 0 | R46: 0 | T46: 44187 | U46: KaushikRay | V46: Pending | W46: sites/Elecsense/Lists/cableTable1 | Y46: NULL | Z46: NULL | AA46: NULL
A47: 46 | B47: B1SWBD0-274 | C47: -- | D47: 0.6/1kV_A_LC_Non-FR_10Cx2.5 | E47: fromEqpTag176 | F47: toEqpTag176 | G47: 555 | H47: SS01 | I47: 555 | J47: PC_B1SWBD0-274 | K47: C-L-10C2.5-D001 | L47: 100 | M47: 0 | N47: 0 | O47: 100 | P47: 200 | Q47: 0 | R47: 0 | S47: Testtesttest | T47: 44276 | U47: KaushikRay | V47: Pending | W47: sites/Elecsense/Lists/cableTable1 | Y47: NULL | Z47: NULL | AA47: NULL
A48: 47 | B48: B1SWBD0-275 | C48: -- | D48: 0.6/1kV_A_LC_Non-FR_10Cx2.5 | E48: fromEqpTag177 | F48: toEqpTag177 | G48: 440 | H48: SS01 | I48: 440 | J48: PC_B1SWBD0-275 | K48: C-L-10C2.5-D001 | L48: 0 | M48: 0 | N48: 0 | O48: 0 | P48: 0 | Q48: 0 | R48: 0 | T48: 44187 | U48: KaushikRay | V48: Pending | W48: sites/Elecsense/Lists/cableTable1 | Y48: NULL | Z48: NULL | AA48: NULL
A49: 48 | B49: B1SWBD0-276 | C49: -- | D49: 0.6/1kV_A_LC_Non-FR_10Cx2.5 | E49: fromEqpTag178 | F49: toEqpTag178 | G49: 633 | H49: SS01 | I49: 633 | J49: PC_B1SWBD0-276 | K49: C-L-10C2.5-D002 | L49: 0 | M49: 0 | N49: 0 | O49: 0 | P49: 0 | Q49: 0 | R49: 0 | T49: 44276 | U49: KaushikRay | V49: Pending | W49: sites/Elecsense/Lists/cableTable1 | Y49: NULL | Z49: NULL | AA49: NULL
A50: 49 | B50: B1SWBD0-277 | C50: -- | D50: 0.6/1kV_A_LC_Non-FR_10Cx2.5 | E50: fromEqpTag179 | F50: toEqpTag179 | G50: 322 | H50: SS01 | I50: 322 | J50: PC_B1SWBD0-277 | K50: C-L-10C2.5-D002 | L50: 0 | M50: 0 | N50: 0 | O50: 0 | P50: 0 | Q50: 0 | R50: 0 | T50: 44276 | U50: KaushikRay | V50: Pending | W50: sites/Elecsense/Lists/cableTable1 | Y50: NULL | Z50: NULL | AA50: NULL
A51: 50 | B51: B1SWBD0-278 | C51: -- | D51: 0.6/1kV_A_LC_Non-FR_10Cx2.5 | E51: fromEqpTag180 | F51: toEqpTag180 | G51: 622 | H51: SS01 | I51: 622 | J51: PC_B1SWBD0-278 | K51: C-L-10C2.5-D003 | L51: 0 | M51: 0 | N51: 0 | O51: 0 | P51: 0 | Q51: 0 | R51: 0 | T51: 44276 | U51: KaushikRay | V51: Pending | W51: sites/Elecsense/Lists/cableTable1 | Y51: NULL | Z51: NULL | AA51: NULL
A52: 51 | B52: B1SWBD0-279 | C52: -- | D52: 0.6/1kV_A_LC_Non-FR_10Cx2.5 | E52: fromEqpTag181 | F52: toEqpTag181 | G52: 330 | H52: SS01 | I52: 330 | J52: PC_B1SWBD0-279 | K52: C-L-10C2.5-D003 | L52: 0 | M52: 0 | N52: 0 | O52: 0 | P52: 0 | Q52: 0 | R52: 0 | T52: 44214 | U52: KaushikRay | V52: Pending | W52: sites/Elecsense/Lists/cableTable1 | Y52: NULL | Z52: NULL | AA52: NULL
A53: 52 | B53: B1SWBD0-280 | C53: -- | D53: 0.6/1kV_A_LC_Non-FR_10Cx2.5 | E53: fromEqpTag182 | F53: toEqpTag182 | G53: 628 | H53: SS01 | I53: 628 | J53: PC_B1SWBD0-280 | K53: C-L-10C2.5-D004 | L53: 0 | M53: 0 | N53: 0 | O53: 0 | P53: 0 | Q53: 0 | R53: 0 | T53: 44187 | U53: KaushikRay | V53: Pending | W53: sites/Elecsense/Lists/cableTable1 | Y53: NULL | Z53: NULL | AA53: NULL
A54: 53 | B54: B1SWBD0-281 | C54: -- | D54: 0.6/1kV_A_LC_Non-FR_10Cx2.5 | E54: fromEqpTag183 | F54: toEqpTag183 | G54: 327 | H54: SS01 | I54: 327 | J54: PC_B1SWBD0-281 | K54: C-L-10C2.5-D004 | L54: 0 | M54: 0 | N54: 0 | O54: 0 | P54: 0 | Q54: 0 | R54: 0 | T54: 44187 | U54: KaushikRay | V54: Pending | W54: sites/Elecsense/Lists/cableTable1 | Y54: NULL | Z54: NULL | AA54: NULL
A55: 54 | B55: B1SWBD0-282 | C55: -- | D55: 0.6/1kV_A_LC_Non-FR_10Cx2.5 | E55: fromEqpTag184 | F55: toEqpTag184 | G55: 647 | H55: SS01 | I55: 647 | J55: PC_B1SWBD0-282 | K55: C-L-10C2.5-D005 | L55: 0 | M55: 0 | N55: 0 | O55: 0 | P55: 0 | Q55: 0 | R55: 0 | T55: 44187 | U55: KaushikRay | V55: Pending | W55: sites/Elecsense/Lists/cableTable1 | Y55: NULL | Z55: NULL | AA55: NULL
A56: 55 | B56: B1RCP00-283 | C56: Segment1 | D56: 0.6/1kV_A_LC_Non-FR_10Cx2.5 | E56: fromEqpTag185 | F56: toEqpTag185 | G56: 1230 | H56: SS01 | I56: 298 | J56: PC_B1RCP00-283 | K56: C-L-10C2.5-D005-1 | L56: 0 | M56: 0 | N56: 0 | O56: 0 | P56: 0 | Q56: 0 | R56: 0 | T56: 44187 | U56: KaushikRay | V56: Pending | W56: sites/Elecsense/Lists/cableTable1 | Y56: NULL | Z56: NULL | AA56: NULL
A57: 56 | B57: B1SWBD0-284 | C57: -- | D57: 0.6/1kV_A_LC_Non-FR_10Cx2.5 | E57: fromEqpTag186 | F57: toEqpTag186 | G57: 893 | H57: SS01 | I57: 893 | J57: PC_B1SWBD0-284 | K57: C-L-10C2.5-D006 | L57: 0 | M57: 0 | N57: 0 | O57: 0 | P57: 0 | Q57: 0 | R57: 0 | T57: 44206 | U57: KaushikRay | V57: Pending | W57: sites/Elecsense/Lists/cableTable1 | Y57: NULL | Z57: NULL | AA57: NULL
A58: 57 | B58: B1SWBD0-285 | C58: Segment2 | D58: 0.6/1kV_A_LC_Non-FR_10Cx2.5 | E58: fromEqpTag187 | F58: toEqpTag187 | G58: 1045 | H58: SS01 | I58: 52 | J58: PC_B1SWBD0-285 | K58: C-L-10C2.5-D006 | L58: 0 | M58: 0 | N58: 0 | O58: 0 | P58: 0 | Q58: 0 | R58: 0 | T58: 44187 | U58: KaushikRay | V58: Pending | W58: sites/Elecsense/Lists/cableTable1 | Y58: NULL | Z58: NULL | AA58: NULL
A59: 58 | B59: B1SWBD0-294 | C59: -- | D59: 0.6/1kV_A_LC_Non-FR_10Cx2.5 | E59: fromEqpTag196 | F59: toEqpTag196 | G59: 597 | H59: SS01 | I59: 597 | J59: PC_B1SWBD0-294 | K59: C-L-10C2.5-D017 | L59: 0 | M59: 0 | N59: 0 | O59: 0 | P59: 0 | Q59: 0 | R59: 0 | T59: 44187 | U59: KaushikRay | V59: Pending | W59: sites/Elecsense/Lists/cableTable1 | Y59: NULL | Z59: NULL | AA59: NULL
... A629: 628 | B629: B1SWBD0-324 | C629: Segment3 | D629: 0.6/1kV_A_LC_Non-FR_10Cx2.5 | E629: fromEqpTag720 | F629: toEqpTag720 | G629: 2069 | H629: SS01 | I629: 995 | J629: PC_B1SWBD0-324 | K629: C-L-10C2.5-D379 | L629: 0 | M629: 0 | N629: 0 | O629: 0 | P629: 0 | Q629: 0 | R629: 0 | T629: 44187 | U629: KaushikRay | V629: Pending | W629: sites/Elecsense/Lists/cableTable1 | Y629: NULL | Z629: NULL | AA629: NULL
A630: 629 | G630: NULL | H630: SS01 | I630: NULL | M630: NULL | N630: NULL | O630: NULL | P630: NULL | Q630: NULL | R630: NULL | T630: NULL | Y630: NULL | Z630: NULL | AA630: NULL
A631: 630 | B631: A1HDB00-179 | C631: -- | D631: 0.6/1kV_A_LC_Non-FR_5Cx2.5 | E631: fromEqpTag81 | F631: toEqpTag81 | G631: 962 | H631: SS01 | I631: 962 | J631: PC_A1HDB00-179 | K631: C-L-5C2.5-D002 | L631: 200 | M631: 0 | N631: 0 | O631: 0 | P631: 0 | Q631: 0 | R631: 0 | S631: Testtest | T631: 44288 | U631: KaushikRay | V631: Pending | W631: sites/Elecsense/Lists/cableTable1 | Y631: NULL | Z631: NULL | AA631: NULL
A632: 631 | B632: A2BM210-180 | C632: -- | D632: 0.6/1kV_A_LC_Non-FR_5Cx2.5 | E632: fromEqpTag82 | F632: toEqpTag82 | G632: 10 | H632: SS01 | I632: 10 | J632: PC_A2BM210-180 | K632: C-L-5C2.5-D002 | L632: 0 | M632: 0 | N632: 0 | O632: 0 | P632: 0 | Q632: 1 | R632: 1 | T632: 44187 | U632: KaushikRay | V632: Pending | W632: sites/Elecsense/Lists/cableTable1 | Y632: NULL | Z632: NULL | AA632: NULL
A633: 632 | B633: A7BM080-181 | C633: -- | D633: 0.6/1kV_A_LC_Non-FR_5Cx2.5 | E633: fromEqpTag83 | F633: toEqpTag83 | G633: 10 | H633: SS01 | I633: 10 | J633: PC_A7BM080-181 | K633: C-L-5C2.5-D002 | L633: 250 | M633: 0 | N633: 0 | O633: 110 | P633: 360 | Q633: 1 | R633: 1 | S633: Alldone. | T633: 44272 | U633: KaushikRay | V633: Pending | W633: sites/Elecsense/Lists/cableTable1 | Y633: NULL | Z633: NULL | AA633: NULL
A634: 633 | B634: A7BM080-182 | C634: -- | D634: 0.6/1kV_A_LC_Non-FR_5Cx2.5 | E634: fromEqpTag84 | F634: toEqpTag84 | G634: 10 | H634: SS01 | I634: 10 | J634: PC_A7BM080-182 | K634: C-L-5C2.5-D002 | L634: 200 | M634: 0 | N634: 0 | O634: 100 | P634: 300 | Q634: 1 | R634: 1 | S634: workisstoppedduetorain | T634: 44288 | U634: KaushikRay | V634: Pending | W634: sites/Elecsense/Lists/cableTable1 | Y634: NULL | Z634: NULL | AA634: NULL
A635: 634 | B635: A3GM010-183 | C635: -- | D635: 0.6/1kV_A_LC_Non-FR_5Cx2.5 | E635: fromEqpTag85 | F635: toEqpTag85 | G635: 5 | H635: SS01 | I635: 5 | J635: PC_A3GM010-183 | K635: C-L-5C2.5-D002 | L635: 0 | M635: 0 | N635: 0 | O635: 0 | P635: 0 | Q635: 1 | R635: 1 | T635: 44187 | U635: KaushikRay | V635: Pending | W635: sites/Elecsense/Lists/cableTable1 | Y635: NULL | Z635: NULL | AA635: NULL
A636: 635 | B636: B1TCP13-221 | C636: -- | D636: 0.6/1kV_A_LC_Non-FR_5Cx2.5 | E636: fromEqpTag123 | F636: toEqpTag123 | G636: 670 | H636: SS01 | I636: 670 | J636: PC_B1TCP13-221 | K636: C-L-5C2.5-D022 | L636: 0 | M636: 0 | N636: 0 | O636: 0 | P636: 0 | Q636: 1 | R636: 1 | T636: 44187 | U636: KaushikRay | V636: Pending | W636: sites/Elecsense/Lists/cableTable1 | Y636: NULL | Z636: NULL | AA636: NULL
A637: 636 | B637: B1TCP12-222 | C637: -- | D637: 0.6/1kV_A_LC_Non-FR_5Cx2.5 | E637: fromEqpTag124 | F637: toEqpTag124 | G637: 315 | H637: SS01 | I637: 315 | J637: PC_B1TCP12-222 | K637: C-L-5C2.5-D022 | L637: 0 | M637: 0 | N637: 0 | O637: 0 | P637: 0 | Q637: 1 | R637: 1 | T637: 44187 | U637: KaushikRay | V637: Pending | W637: sites/Elecsense/Lists/cableTable1 | Y637: NULL | Z637: NULL | AA637: NULL
A638: 637 | B638: A2BM310-223 | C638: -- | D638: 0.6/1kV_A_LC_Non-FR_5Cx2.5 | E638: fromEqpTag125 | F638: toEqpTag125 | G638: 10 | H638: SS01 | I638: 10 | J638: PC_A2BM310-223 | K638: C-L-5C2.5-D022 | L638: 0 | M638: 0 | N638: 0 | O638: 0 | P638: 0 | Q638: 1 | R638: 1 | T638: 44187 | U638: KaushikRay | V638: Pending | W638: sites/Elecsense/Lists/cableTable1 | Y638: NULL | Z638: NULL | AA638: NULL
A639: 638 | B639: SealGa-224 | C639: -- | D639: 0.6/1kV_A_LC_Non-FR_5Cx2.5 | E639: fromEqpTag126 | F639: toEqpTag126 | G639: 5 | H639: SS01 | I639: 5 | J639: PC_SealGa-224 | K639: C-L-5C2.5-D022 | L639: 0 | M639: 0 | N639: 0 | O639: 0 | P639: 0 | Q639: 1 | R639: 1 | T639: 44187 | U639: KaushikRay | V639: Pending | W639: sites/Elecsense/Lists/cableTable1 | Y639: NULL | Z639: NULL | AA639: NULL
A640: 639 | B640: B1ACUPS-125 | C640: -- | D640: 0.6/1kV_A_LC_Non-FR_3Cx2.5 | E640: fromEqpTag27 | F640: toEqpTag27 | G640: 279 | H640: SS01 | I640: 279 | J640: PC_B1ACUPS-125 | K640: C-L-3C2.5-D013 | L640: 0 | M640: 0 | N640: 0 | O640: 0 | P640: 0 | Q640: 1 | R640: 1 | T640: 44187 | U640: KaushikRay | V640: Pending | W640: sites/Elecsense/Lists/cableTable1 | Y640: NULL | Z640: NULL | AA640: NULL
A641: 640 | B641: B1DCUPS-126 | C641: -- | D641: 0.6/1kV_A_LC_Non-FR_3Cx2.5 | E641: fromEqpTag28 | F641: toEqpTag28 | G641: 279 | H641: SS01 | I641: 279 | J641: PC_B1DCUPS-126 | K641: C-L-3C2.5-D013 | L641: 0 | M641: 0 | N641: 0 | O641: 0 | P641: 0 | Q641: 0 | R641: 0 | T641: 44187 | U641: KaushikRay | V641: Pending | W641: sites/Elecsense/Lists/cableTable1 | Y641: NULL | Z641: NULL | AA641: NULL
...

Sheet DrumCopySql
A1: uid | B1: drumTag | C1: cableSpec | D1: manufLength | E1: designLength | F1: LenxDiainmm | G1: weightKg | H1: cutLength | I1: commLength | J1: geoLocation
A2: 1 | B2: C-L-5C2.5-D002 | C2: 0.6/1kV_A_LC_Non-FR_5Cx2.5 | D2: 1000 | E2: 983 | F2: 3775x1098 | G2: 908 | H2: 0 | I2: 0 | J2: 25.110376,55.151551
A3: 2 | B3: C-L-5C2.5-D022 | C3: 0.6/1kV_A_LC_Non-FR_5Cx2.5 | D3: 1000 | E3: 992 | F3: 4426x1459 | G3: 872 | H3: 0 | I3: 0 | J3: 25.110376,55.14985
A4: 3 | B4: C-L-3C2.5-D013 | C4: 0.6/1kV_A_LC_Non-FR_3Cx2.5 | D4: 1000 | E4: 997 | F4: 3063x1222 | G4: 534 | H4: 0 | I4: 0 | J4: 25.110376,55.117362
A5: 4 | B5: C-L-5C2.5-D024 | C5: 0.6/1kV_A_LC_Non-FR_5Cx2.5 | D5: 1000 | E5: 983 | F5: 3223x1535 | G5: 583 | H5: 0 | I5: 0 | J5: 25.110376,55.115714
A6: 5 | B6: C-L-5C2.5-D026 | C6: 0.6/1kV_A_LC_Non-FR_5Cx2.5 | D6: 1000 | E6: 982 | F6: 2262x1785 | G6: 726 | H6: 0 | I6: 0 | J6: 25.110376,55.141904
A7: 6 | B7: C-L-3C2.5-D014 | C7: 0.6/1kV_A_LC_Non-FR_3Cx2.5 | D7: 1000 | E7: 982 | F7: 3670x1971 | G7: 908 | H7: 0 | I7: 0 | J7: 25.110376,55.146833
A8: 7 | B8: C-L-3C2.5-D015 | C8: 0.6/1kV_A_LC_Non-FR_3Cx2.5 | D8: 1000 | E8: 999 | F8: 2905x1098 | G8: 593 | H8: 0 | I8: 0 | J8: 25.110376,55.1156
A9: 8 | B9: C-L-3C2.5-D016 | C9: 0.6/1kV_A_LC_Non-FR_3Cx2.5 | D9: 1000 | E9: 997 | F9: 2390x1281 | G9: 604 | H9: 0 | I9: 0 | J9: 25.110376,55.151534
A10: 9 | B10: C-L-3C2.5-D018 | C10: 0.6/1kV_A_LC_Non-FR_3Cx2.5 | D10: 1000 | E10: 984 | F10: 4447x1862 | G10: 875 | H10: 0 | I10: 0 | J10: 25.110376,55.141051
A11: 10 | B11: C-L-3C2.5-D019 | C11: 0.6/1kV_A_LC_Non-FR_3Cx2.5 | D11: 1000 | E11: 997 | F11: 3888x1359 | G11: 859 | H11: 0 | I11: 0 | J11: 25.110376,55.137743
A12: 11 | B12: C-L-3C2.5-D020 | C12: 0.6/1kV_A_LC_Non-FR_3Cx2.5 | D12: 1000 | E12: 978 | F12: 2786x1474 | G12: 747 | H12: 0 | I12: 0 | J12: 25.110376,55.111092
A13: 12 | B13: C-L-3C2.5-D021 | C13: 0.6/1kV_A_LC_Non-FR_3Cx2.5 | D13: 1000 | E13: 993 | F13: 1518x1412 | G13: 653 | H13: 0 | I13: 0 | J13: 25.110376,55.133899
... A434: 433 | B434: C-L-3C2.5-D001 | C434: 0.6/1kV_A_LC_Non-FR_3Cx2.5 | D434: 990 | E434: 985 | F434: 4091x1244 | G434: 776 | H434: 0 | I434: 0 | J434: NULL
